Workbook

Sheet Overview
A1: LittleStory AI — Jira Board & Delivery Workbook
A2: Little Stories. Big Imagination. · Generated 29 Oct 2026 from the master orchestrator prompt and the Figma Make design pack
A4: Project | B4: LittleStory AI – child-friendly AI storytelling app (ages 3–12) with parent controls
A5: Objective | B5: Production-quality, maintainable, accessible, multilingual native Android app that faithfully implements the approved Figma design, with no hardcoded values.
A6: Platform | B6: Native Android · Kotlin · Jetpack Compose · Material 3 (customised)
A7: Languages | B7: MVP: English (default & fallback) and Kannada (ಕನ್ನಡ). Future languages added via resources + registry only (no feature-code change).
A8: Design source | B8: https://www.figma.com/make/2DYtUW39GtnsDpUd5jSu6x/Mobile-App-UI-Prototype?p=f&t=7bdm57yPvNI3NZ8f-0
A9: Design pack | B9: docs/design/ – 22 screenshots (18 screens), design-tokens.json, LittleStory_Figma_Design_Details.md (see 'Screens' and 'Design Gallery' sheets)
A10: Repository | B10: https://github.com/shivayogih/LittleStory
A11: Dev environment | B11: Windows + macOS · Android Studio · Claude Code CLI · GitHub · GitHub Copilot
A12: MVP scope | B12: 18 designed screens with deterministic local mock data in EN/KN; simulated story generation, narration, downloads and demo subscription (clearly labelled).
A13: Out of scope (MVP) | B13: Real AI provider, backend, auth, cloud sync, analytics, real payments, production TTS/streaming, remote notifications, runtime machine translation, languages beyond EN/KN in the shipped UI.
A14: Architecture principles | B14: Clean layers (UI → ViewModel → use case → repository) · immutable UiState + StateFlow · design tokens only · string resources only (UiText in VMs) · central AppConfig & feature flags · per-language mock JSON · Hilt DI · no circular module deps
A15: No-hardcoding policy | B15: Text → strings.xml (EN + KN) · colours/dims/type → design tokens · limits/timings/options → AppConfig · routes → typed destinations · mock data → assets/mock JSON · versions → libs.versions.toml · languages → SupportedLanguage registry
... A19: Key risks | B19: Old 'LittleKatha' brand in designs · 7 design languages vs EN/KN · fonts lack Kannada glyphs · missing designs (splash, language prefs, privacy, help) · contrast & touch targets · Kannada reviewer availability. See 'Risks & Questions' · cloud workspace cannot build Android (R-21) · default branch misconfigured (R-22).
A21: Progress (live)
A22: Tickets total | B22: =COUNTA(Backlog!$A$2:$A$300)
A23: Done | B23: =COUNTIF(Backlog!$AD$2:$AD$300,"Done")
A24: In progress / in review | B24: =COUNTIF(Backlog!$AD$2:$AD$300,"In Progress")+COUNTIF(Backlog!$AD$2:$AD$300,"In Review")
A25: Blocked / needs clarification | B25: =COUNTIF(Backlog!$AD$2:$AD$300,"Blocked")+COUNTIF(Backlog!$AD$2:$AD$300,"Needs Clarification")
A26: Story points total | B26: =SUM(Backlog!$U$2:$U$300)
A27: Story points done | B27: =SUMIF(Backlog!$AD$2:$AD$300,"Done",Backlog!$U$2:$U$300)
A28: % points complete | B28: =IF(B26=0,0,B27/B26)
A30: How to use
A31: Board | B31: Kanban view – updates automatically when you change Status in 'Backlog'.
A32: Backlog | B32: Edit Status, Assignee, PR Link, Test Evidence, Actual Result, Kannada Translation Status (dropdowns provided). Do not rename Issue Keys.
A33: Screens / Design Gallery | B33: Screenshot thumbnails, full design details, links to the full screenshots in docs/design/screens/ and to Figma.
A34: Translations | B34: Fill the Kannada column; keep status 'Needs native review' until a fluent reviewer approves.
A35: Legend | B35: Editable columns have a cream header note. Grey 'Board Key' column in Backlog is a formula – do not edit.

Sheet Board
A1: Kanban Board
A2: Live view of the Backlog sheet – change a ticket's Status there and it moves here. Columns list 'Key · Summary'.
B4: To Do | C4: In Progress | D4: In Review | E4: Blocked | F4: Done | H4: 'Needs Clarification' tickets appear in Dashboard → By status.
B5: =COUNTIF(Backlog!$AD$2:$AD$300,"To Do")&" tickets · "&SUMIF(Backlog!$AD$2:$AD$300,"To Do",Backlog!$U$2:$U$300)&" pts" | C5: =COUNTIF(Backlog!$AD$2:$AD$300,"In Progress")&" tickets · "&SUMIF(Backlog!$AD$2:$AD$300,"In Progress",Backlog!$U$2:$U$300)&" pts" | D5: =COUNTIF(Backlog!$AD$2:$AD$300,"In Review")&" tickets · "&SUMIF(Backlog!$AD$2:$AD$300,"In Review",Backlog!$U$2:$U$300)&" pts" | E5: =COUNTIF(Backlog!$AD$2:$AD$300,"Blocked")&" tickets · "&SUMIF(Backlog!$AD$2:$AD$300,"Blocked",Backlog!$U$2:$U$300)&" pts" | F5: =COUNTIF(Backlog!$AD$2:$AD$300,"Done")&" tickets · "&SUMIF(Backlog!$AD$2:$AD$300,"Done",Backlog!$U$2:$U$300)&" pts"
B6: =IFERROR(INDEX(Backlog!$A$2:$A$300,MATCH("To Do|1",Backlog!$AL$2:$AL$300,0))&" · "&INDEX(Backlog!$D$2:$D$300,MATCH("To Do|1",Backlog!$AL$2:$AL$300,0)),"") | C6: =IFERROR(INDEX(Backlog!$A$2:$A$300,MATCH("In Progress|1",Backlog!$AL$2:$AL$300,0))&" · "&INDEX(Backlog!$D$2:$D$300,MATCH("In Progress|1",Backlog!$AL$2:$AL$300,0)),"") | D6: =IFERROR(INDEX(Backlog!$A$2:$A$300,MATCH("In Review|1",Backlog!$AL$2:$AL$300,0))&" · "&INDEX(Backlog!$D$2:$D$300,MATCH("In Review|1",Backlog!$AL$2:$AL$300,0)),"") | E6: =IFERROR(INDEX(Backlog!$A$2:$A$300,MATCH("Blocked|1",Backlog!$AL$2:$AL$300,0))&" · "&INDEX(Backlog!$D$2:$D$300,MATCH("Blocked|1",Backlog!$AL$2:$AL$300,0)),"") | F6: =IFERROR(INDEX(Backlog!$A$2:$A$300,MATCH("Done|1",Backlog!$AL$2:$AL$300,0))&" · "&INDEX(Backlog!$D$2:$D$300,MATCH("Done|1",Backlog!$AL$2:$AL$300,0)),"")
B7: =IFERROR(INDEX(Backlog!$A$2:$A$300,MATCH("To Do|2",Backlog!$AL$2:$AL$300,0))&" · "&INDEX(Backlog!$D$2:$D$300,MATCH("To Do|2",Backlog!$AL$2:$AL$300,0)),"") | C7: =IFERROR(INDEX(Backlog!$A$2:$A$300,MATCH("In Progress|2",Backlog!$AL$2:$AL$300,0))&" · "&INDEX(Backlog!$D$2:$D$300,MATCH("In Progress|2",Backlog!$AL$2:$AL$300,0)),"") | D7: =IFERROR(INDEX(Backlog!$A$2:$A$300,MATCH("In Review|2",Backlog!$AL$2:$AL$300,0))&" · "&INDEX(Backlog!$D$2:$D$300,MATCH("In Review|2",Backlog!$AL$2:$AL$300,0)),"") | E7: =IFERROR(INDEX(Backlog!$A$2:$A$300,MATCH("Blocked|2",Backlog!$AL$2:$AL$300,0))&" · "&INDEX(Backlog!$D$2:$D$300,MATCH("Blocked|2",Backlog!$AL$2:$AL$300,0)),"") | F7: =IFERROR(INDEX(Backlog!$A$2:$A$300,MATCH("Done|2",Backlog!$AL$2:$AL$300,0))&" · "&INDEX(Backlog!$D$2:$D$300,MATCH("Done|2",Backlog!$AL$2:$AL$300,0)),"")
B8: =IFERROR(INDEX(Backlog!$A$2:$A$300,MATCH("To Do|3",Backlog!$AL$2:$AL$300,0))&" · "&INDEX(Backlog!$D$2:$D$300,MATCH("To Do|3",Backlog!$AL$2:$AL$300,0)),"") | C8: =IFERROR(INDEX(Backlog!$A$2:$A$300,MATCH("In Progress|3",Backlog!$AL$2:$AL$300,0))&" · "&INDEX(Backlog!$D$2:$D$300,MATCH("In Progress|3",Backlog!$AL$2:$AL$300,0)),"") | D8: =IFERROR(INDEX(Backlog!$A$2:$A$300,MATCH("In Review|3",Backlog!$AL$2:$AL$300,0))&" · "&INDEX(Backlog!$D$2:$D$300,MATCH("In Review|3",Backlog!$AL$2:$AL$300,0)),"") | E8: =IFERROR(INDEX(Backlog!$A$2:$A$300,MATCH("Blocked|3",Backlog!$AL$2:$AL$300,0))&" · "&INDEX(Backlog!$D$2:$D$300,MATCH("Blocked|3",Backlog!$AL$2:$AL$300,0)),"") | F8: =IFERROR(INDEX(Backlog!$A$2:$A$300,MATCH("Done|3",Backlog!$AL$2:$AL$300,0))&" · "&INDEX(Backlog!$D$2:$D$300,MATCH("Done|3",Backlog!$AL$2:$AL$300,0)),"")
B9: =IFERROR(INDEX(Backlog!$A$2:$A$300,MATCH("To Do|4",Backlog!$AL$2:$AL$300,0))&" · "&INDEX(Backlog!$D$2:$D$300,MATCH("To Do|4",Backlog!$AL$2:$AL$300,0)),"") | C9: =IFERROR(INDEX(Backlog!$A$2:$A$300,MATCH("In Progress|4",Backlog!$AL$2:$AL$300,0))&" · "&INDEX(Backlog!$D$2:$D$300,MATCH("In Progress|4",Backlog!$AL$2:$AL$300,0)),"") | D9: =IFERROR(INDEX(Backlog!$A$2:$A$300,MATCH("In Review|4",Backlog!$AL$2:$AL$300,0))&" · "&INDEX(Backlog!$D$2:$D$300,MATCH("In Review|4",Backlog!$AL$2:$AL$300,0)),"") | E9: =IFERROR(INDEX(Backlog!$A$2:$A$300,MATCH("Blocked|4",Backlog!$AL$2:$AL$300,0))&" · "&INDEX(Backlog!$D$2:$D$300,MATCH("Blocked|4",Backlog!$AL$2:$AL$300,0)),"") | F9: =IFERROR(INDEX(Backlog!$A$2:$A$300,MATCH("Done|4",Backlog!$AL$2:$AL$300,0))&" · "&INDEX(Backlog!$D$2:$D$300,MATCH("Done|4",Backlog!$AL$2:$AL$300,0)),"")
B10: =IFERROR(INDEX(Backlog!$A$2:$A$300,MATCH("To Do|5",Backlog!$AL$2:$AL$300,0))&" · "&INDEX(Backlog!$D$2:$D$300,MATCH("To Do|5",Backlog!$AL$2:$AL$300,0)),"") | C10: =IFERROR(INDEX(Backlog!$A$2:$A$300,MATCH("In Progress|5",Backlog!$AL$2:$AL$300,0))&" · "&INDEX(Backlog!$D$2:$D$300,MATCH("In Progress|5",Backlog!$AL$2:$AL$300,0)),"") | D10: =IFERROR(INDEX(Backlog!$A$2:$A$300,MATCH("In Review|5",Backlog!$AL$2:$AL$300,0))&" · "&INDEX(Backlog!$D$2:$D$300,MATCH("In Review|5",Backlog!$AL$2:$AL$300,0)),"") | E10: =IFERROR(INDEX(Backlog!$A$2:$A$300,MATCH("Blocked|5",Backlog!$AL$2:$AL$300,0))&" · "&INDEX(Backlog!$D$2:$D$300,MATCH("Blocked|5",Backlog!$AL$2:$AL$300,0)),"") | F10: =IFERROR(INDEX(Backlog!$A$2:$A$300,MATCH("Done|5",Backlog!$AL$2:$AL$300,0))&" · "&INDEX(Backlog!$D$2:$D$300,MATCH("Done|5",Backlog!$AL$2:$AL$300,0)),"")
B11: =IFERROR(INDEX(Backlog!$A$2:$A$300,MATCH("To Do|6",Backlog!$AL$2:$AL$300,0))&" · "&INDEX(Backlog!$D$2:$D$300,MATCH("To Do|6",Backlog!$AL$2:$AL$300,0)),"") | C11: =IFERROR(INDEX(Backlog!$A$2:$A$300,MATCH("In Progress|6",Backlog!$AL$2:$AL$300,0))&" · "&INDEX(Backlog!$D$2:$D$300,MATCH("In Progress|6",Backlog!$AL$2:$AL$300,0)),"") | D11: =IFERROR(INDEX(Backlog!$A$2:$A$300,MATCH("In Review|6",Backlog!$AL$2:$AL$300,0))&" · "&INDEX(Backlog!$D$2:$D$300,MATCH("In Review|6",Backlog!$AL$2:$AL$300,0)),"") | E11: =IFERROR(INDEX(Backlog!$A$2:$A$300,MATCH("Blocked|6",Backlog!$AL$2:$AL$300,0))&" · "&INDEX(Backlog!$D$2:$D$300,MATCH("Blocked|6",Backlog!$AL$2:$AL$300,0)),"") | F11: =IFERROR(INDEX(Backlog!$A$2:$A$300,MATCH("Done|6",Backlog!$AL$2:$AL$300,0))&" · "&INDEX(Backlog!$D$2:$D$300,MATCH("Done|6",Backlog!$AL$2:$AL$300,0)),"")
B12: =IFERROR(INDEX(Backlog!$A$2:$A$300,MATCH("To Do|7",Backlog!$AL$2:$AL$300,0))&" · "&INDEX(Backlog!$D$2:$D$300,MATCH("To Do|7",Backlog!$AL$2:$AL$300,0)),"") | C12: =IFERROR(INDEX(Backlog!$A$2:$A$300,MATCH("In Progress|7",Backlog!$AL$2:$AL$300,0))&" · "&INDEX(Backlog!$D$2:$D$300,MATCH("In Progress|7",Backlog!$AL$2:$AL$300,0)),"") | D12: =IFERROR(INDEX(Backlog!$A$2:$A$300,MATCH("In Review|7",Backlog!$AL$2:$AL$300,0))&" · "&INDEX(Backlog!$D$2:$D$300,MATCH("In Review|7",Backlog!$AL$2:$AL$300,0)),"") | E12: =IFERROR(INDEX(Backlog!$A$2:$A$300,MATCH("Blocked|7",Backlog!$AL$2:$AL$300,0))&" · "&INDEX(Backlog!$D$2:$D$300,MATCH("Blocked|7",Backlog!$AL$2:$AL$300,0)),"") | F12: =IFERROR(INDEX(Backlog!$A$2:$A$300,MATCH("Done|7",Backlog!$AL$2:$AL$300,0))&" · "&INDEX(Backlog!$D$2:$D$300,MATCH("Done|7",Backlog!$AL$2:$AL$300,0)),"")
B13: =IFERROR(INDEX(Backlog!$A$2:$A$300,MATCH("To Do|8",Backlog!$AL$2:$AL$300,0))&" · "&INDEX(Backlog!$D$2:$D$300,MATCH("To Do|8",Backlog!$AL$2:$AL$300,0)),"") | C13: =IFERROR(INDEX(Backlog!$A$2:$A$300,MATCH("In Progress|8",Backlog!$AL$2:$AL$300,0))&" · "&INDEX(Backlog!$D$2:$D$300,MATCH("In Progress|8",Backlog!$AL$2:$AL$300,0)),"") | D13: =IFERROR(INDEX(Backlog!$A$2:$A$300,MATCH("In Review|8",Backlog!$AL$2:$AL$300,0))&" · "&INDEX(Backlog!$D$2:$D$300,MATCH("In Review|8",Backlog!$AL$2:$AL$300,0)),"") | E13: =IFERROR(INDEX(Backlog!$A$2:$A$300,MATCH("Blocked|8",Backlog!$AL$2:$AL$300,0))&" · "&INDEX(Backlog!$D$2:$D$300,MATCH("Blocked|8",Backlog!$AL$2:$AL$300,0)),"") | F13: =IFERROR(INDEX(Backlog!$A$2:$A$300,MATCH("Done|8",Backlog!$AL$2:$AL$300,0))&" · "&INDEX(Backlog!$D$2:$D$300,MATCH("Done|8",Backlog!$AL$2:$AL$300,0)),"")
B14: =IFERROR(INDEX(Backlog!$A$2:$A$300,MATCH("To Do|9",Backlog!$AL$2:$AL$300,0))&" · "&INDEX(Backlog!$D$2:$D$300,MATCH("To Do|9",Backlog!$AL$2:$AL$300,0)),"") | C14: =IFERROR(INDEX(Backlog!$A$2:$A$300,MATCH("In Progress|9",Backlog!$AL$2:$AL$300,0))&" · "&INDEX(Backlog!$D$2:$D$300,MATCH("In Progress|9",Backlog!$AL$2:$AL$300,0)),"") | D14: =IFERROR(INDEX(Backlog!$A$2:$A$300,MATCH("In Review|9",Backlog!$AL$2:$AL$300,0))&" · "&INDEX(Backlog!$D$2:$D$300,MATCH("In Review|9",Backlog!$AL$2:$AL$300,0)),"") | E14: =IFERROR(INDEX(Backlog!$A$2:$A$300,MATCH("Blocked|9",Backlog!$AL$2:$AL$300,0))&" · "&INDEX(Backlog!$D$2:$D$300,MATCH("Blocked|9",Backlog!$AL$2:$AL$300,0)),"") | F14: =IFERROR(INDEX(Backlog!$A$2:$A$300,MATCH("Done|9",Backlog!$AL$2:$AL$300,0))&" · "&INDEX(Backlog!$D$2:$D$300,MATCH("Done|9",Backlog!$AL$2:$AL$300,0)),"")
B15: =IFERROR(INDEX(Backlog!$A$2:$A$300,MATCH("To Do|10",Backlog!$AL$2:$AL$300,0))&" · "&INDEX(Backlog!$D$2:$D$300,MATCH("To Do|10",Backlog!$AL$2:$AL$300,0)),"") | C15: =IFERROR(INDEX(Backlog!$A$2:$A$300,MATCH("In Progress|10",Backlog!$AL$2:$AL$300,0))&" · "&INDEX(Backlog!$D$2:$D$300,MATCH("In Progress|10",Backlog!$AL$2:$AL$300,0)),"") | D15: =IFERROR(INDEX(Backlog!$A$2:$A$300,MATCH("In Review|10",Backlog!$AL$2:$AL$300,0))&" · "&INDEX(Backlog!$D$2:$D$300,MATCH("In Review|10",Backlog!$AL$2:$AL$300,0)),"") | E15: =IFERROR(INDEX(Backlog!$A$2:$A$300,MATCH("Blocked|10",Backlog!$AL$2:$AL$300,0))&" · "&INDEX(Backlog!$D$2:$D$300,MATCH("Blocked|10",Backlog!$AL$2:$AL$300,0)),"") | F15: =IFERROR(INDEX(Backlog!$A$2:$A$300,MATCH("Done|10",Backlog!$AL$2:$AL$300,0))&" · "&INDEX(Backlog!$D$2:$D$300,MATCH("Done|10",Backlog!$AL$2:$AL$300,0)),"")
B16: =IFERROR(INDEX(Backlog!$A$2:$A$300,MATCH("To Do|11",Backlog!$AL$2:$AL$300,0))&" · "&INDEX(Backlog!$D$2:$D$300,MATCH("To Do|11",Backlog!$AL$2:$AL$300,0)),"") | C16: =IFERROR(INDEX(Backlog!$A$2:$A$300,MATCH("In Progress|11",Backlog!$AL$2:$AL$300,0))&" · "&INDEX(Backlog!$D$2:$D$300,MATCH("In Progress|11",Backlog!$AL$2:$AL$300,0)),"") | D16: =IFERROR(INDEX(Backlog!$A$2:$A$300,MATCH("In Review|11",Backlog!$AL$2:$AL$300,0))&" · "&INDEX(Backlog!$D$2:$D$300,MATCH("In Review|11",Backlog!$AL$2:$AL$300,0)),"") | E16: =IFERROR(INDEX(Backlog!$A$2:$A$300,MATCH("Blocked|11",Backlog!$AL$2:$AL$300,0))&" · "&INDEX(Backlog!$D$2:$D$300,MATCH("Blocked|11",Backlog!$AL$2:$AL$300,0)),"") | F16: =IFERROR(INDEX(Backlog!$A$2:$A$300,MATCH("Done|11",Backlog!$AL$2:$AL$300,0))&" · "&INDEX(Backlog!$D$2:$D$300,MATCH("Done|11",Backlog!$AL$2:$AL$300,0)),"")
B17: =IFERROR(INDEX(Backlog!$A$2:$A$300,MATCH("To Do|12",Backlog!$AL$2:$AL$300,0))&" · "&INDEX(Backlog!$D$2:$D$300,MATCH("To Do|12",Backlog!$AL$2:$AL$300,0)),"") | C17: =IFERROR(INDEX(Backlog!$A$2:$A$300,MATCH("In Progress|12",Backlog!$AL$2:$AL$300,0))&" · "&INDEX(Backlog!$D$2:$D$300,MATCH("In Progress|12",Backlog!$AL$2:$AL$300,0)),"") | D17: =IFERROR(INDEX(Backlog!$A$2:$A$300,MATCH("In Review|12",Backlog!$AL$2:$AL$300,0))&" · "&INDEX(Backlog!$D$2:$D$300,MATCH("In Review|12",Backlog!$AL$2:$AL$300,0)),"") | E17: =IFERROR(INDEX(Backlog!$A$2:$A$300,MATCH("Blocked|12",Backlog!$AL$2:$AL$300,0))&" · "&INDEX(Backlog!$D$2:$D$300,MATCH("Blocked|12",Backlog!$AL$2:$AL$300,0)),"") | F17: =IFERROR(INDEX(Backlog!$A$2:$A$300,MATCH("Done|12",Backlog!$AL$2:$AL$300,0))&" · "&INDEX(Backlog!$D$2:$D$300,MATCH("Done|12",Backlog!$AL$2:$AL$300,0)),"")
B18: =IFERROR(INDEX(Backlog!$A$2:$A$300,MATCH("To Do|13",Backlog!$AL$2:$AL$300,0))&" · "&INDEX(Backlog!$D$2:$D$300,MATCH("To Do|13",Backlog!$AL$2:$AL$300,0)),"") | C18: =IFERROR(INDEX(Backlog!$A$2:$A$300,MATCH("In Progress|13",Backlog!$AL$2:$AL$300,0))&" · "&INDEX(Backlog!$D$2:$D$300,MATCH("In Progress|13",Backlog!$AL$2:$AL$300,0)),"") | D18: =IFERROR(INDEX(Backlog!$A$2:$A$300,MATCH("In Review|13",Backlog!$AL$2:$AL$300,0))&" · "&INDEX(Backlog!$D$2:$D$300,MATCH("In Review|13",Backlog!$AL$2:$AL$300,0)),"") | E18: =IFERROR(INDEX(Backlog!$A$2:$A$300,MATCH("Blocked|13",Backlog!$AL$2:$AL$300,0))&" · "&INDEX(Backlog!$D$2:$D$300,MATCH("Blocked|13",Backlog!$AL$2:$AL$300,0)),"") | F18: =IFERROR(INDEX(Backlog!$A$2:$A$300,MATCH("Done|13",Backlog!$AL$2:$AL$300,0))&" · "&INDEX(Backlog!$D$2:$D$300,MATCH("Done|13",Backlog!$AL$2:$AL$300,0)),"")
B19: =IFERROR(INDEX(Backlog!$A$2:$A$300,MATCH("To Do|14",Backlog!$AL$2:$AL$300,0))&" · "&INDEX(Backlog!$D$2:$D$300,MATCH("To Do|14",Backlog!$AL$2:$AL$300,0)),"") | C19: =IFERROR(INDEX(Backlog!$A$2:$A$300,MATCH("In Progress|14",Backlog!$AL$2:$AL$300,0))&" · "&INDEX(Backlog!$D$2:$D$300,MATCH("In Progress|14",Backlog!$AL$2:$AL$300,0)),"") | D19: =IFERROR(INDEX(Backlog!$A$2:$A$300,MATCH("In Review|14",Backlog!$AL$2:$AL$300,0))&" · "&INDEX(Backlog!$D$2:$D$300,MATCH("In Review|14",Backlog!$AL$2:$AL$300,0)),"") | E19: =IFERROR(INDEX(Backlog!$A$2:$A$300,MATCH("Blocked|14",Backlog!$AL$2:$AL$300,0))&" · "&INDEX(Backlog!$D$2:$D$300,MATCH("Blocked|14",Backlog!$AL$2:$AL$300,0)),"") | F19: =IFERROR(INDEX(Backlog!$A$2:$A$300,MATCH("Done|14",Backlog!$AL$2:$AL$300,0))&" · "&INDEX(Backlog!$D$2:$D$300,MATCH("Done|14",Backlog!$AL$2:$AL$300,0)),"")
B20: =IFERROR(INDEX(Backlog!$A$2:$A$300,MATCH("To Do|15",Backlog!$AL$2:$AL$300,0))&" · "&INDEX(Backlog!$D$2:$D$300,MATCH("To Do|15",Backlog!$AL$2:$AL$300,0)),"") | C20: =IFERROR(INDEX(Backlog!$A$2:$A$300,MATCH("In Progress|15",Backlog!$AL$2:$AL$300,0))&" · "&INDEX(Backlog!$D$2:$D$300,MATCH("In Progress|15",Backlog!$AL$2:$AL$300,0)),"") | D20: =IFERROR(INDEX(Backlog!$A$2:$A$300,MATCH("In Review|15",Backlog!$AL$2:$AL$300,0))&" · "&INDEX(Backlog!$D$2:$D$300,MATCH("In Review|15",Backlog!$AL$2:$AL$300,0)),"") | E20: =IFERROR(INDEX(Backlog!$A$2:$A$300,MATCH("Blocked|15",Backlog!$AL$2:$AL$300,0))&" · "&INDEX(Backlog!$D$2:$D$300,MATCH("Blocked|15",Backlog!$AL$2:$AL$300,0)),"") | F20: =IFERROR(INDEX(Backlog!$A$2:$A$300,MATCH("Done|15",Backlog!$AL$2:$AL$300,0))&" · "&INDEX(Backlog!$D$2:$D$300,MATCH("Done|15",Backlog!$AL$2:$AL$300,0)),"")
B21: =IFERROR(INDEX(Backlog!$A$2:$A$300,MATCH("To Do|16",Backlog!$AL$2:$AL$300,0))&" · "&INDEX(Backlog!$D$2:$D$300,MATCH("To Do|16",Backlog!$AL$2:$AL$300,0)),"") | C21: =IFERROR(INDEX(Backlog!$A$2:$A$300,MATCH("In Progress|16",Backlog!$AL$2:$AL$300,0))&" · "&INDEX(Backlog!$D$2:$D$300,MATCH("In Progress|16",Backlog!$AL$2:$AL$300,0)),"") | D21: =IFERROR(INDEX(Backlog!$A$2:$A$300,MATCH("In Review|16",Backlog!$AL$2:$AL$300,0))&" · "&INDEX(Backlog!$D$2:$D$300,MATCH("In Review|16",Backlog!$AL$2:$AL$300,0)),"") | E21: =IFERROR(INDEX(Backlog!$A$2:$A$300,MATCH("Blocked|16",Backlog!$AL$2:$AL$300,0))&" · "&INDEX(Backlog!$D$2:$D$300,MATCH("Blocked|16",Backlog!$AL$2:$AL$300,0)),"") | F21: =IFERROR(INDEX(Backlog!$A$2:$A$300,MATCH("Done|16",Backlog!$AL$2:$AL$300,0))&" · "&INDEX(Backlog!$D$2:$D$300,MATCH("Done|16",Backlog!$AL$2:$AL$300,0)),"")
B22: =IFERROR(INDEX(Backlog!$A$2:$A$300,MATCH("To Do|17",Backlog!$AL$2:$AL$300,0))&" · "&INDEX(Backlog!$D$2:$D$300,MATCH("To Do|17",Backlog!$AL$2:$AL$300,0)),"") | C22: =IFERROR(INDEX(Backlog!$A$2:$A$300,MATCH("In Progress|17",Backlog!$AL$2:$AL$300,0))&" · "&INDEX(Backlog!$D$2:$D$300,MATCH("In Progress|17",Backlog!$AL$2:$AL$300,0)),"") | D22: =IFERROR(INDEX(Backlog!$A$2:$A$300,MATCH("In Review|17",Backlog!$AL$2:$AL$300,0))&" · "&INDEX(Backlog!$D$2:$D$300,MATCH("In Review|17",Backlog!$AL$2:$AL$300,0)),"") | E22: =IFERROR(INDEX(Backlog!$A$2:$A$300,MATCH("Blocked|17",Backlog!$AL$2:$AL$300,0))&" · "&INDEX(Backlog!$D$2:$D$300,MATCH("Blocked|17",Backlog!$AL$2:$AL$300,0)),"") | F22: =IFERROR(INDEX(Backlog!$A$2:$A$300,MATCH("Done|17",Backlog!$AL$2:$AL$300,0))&" · "&INDEX(Backlog!$D$2:$D$300,MATCH("Done|17",Backlog!$AL$2:$AL$300,0)),"")
B23: =IFERROR(INDEX(Backlog!$A$2:$A$300,MATCH("To Do|18",Backlog!$AL$2:$AL$300,0))&" · "&INDEX(Backlog!$D$2:$D$300,MATCH("To Do|18",Backlog!$AL$2:$AL$300,0)),"") | C23: =IFERROR(INDEX(Backlog!$A$2:$A$300,MATCH("In Progress|18",Backlog!$AL$2:$AL$300,0))&" · "&INDEX(Backlog!$D$2:$D$300,MATCH("In Progress|18",Backlog!$AL$2:$AL$300,0)),"") | D23: =IFERROR(INDEX(Backlog!$A$2:$A$300,MATCH("In Review|18",Backlog!$AL$2:$AL$300,0))&" · "&INDEX(Backlog!$D$2:$D$300,MATCH("In Review|18",Backlog!$AL$2:$AL$300,0)),"") | E23: =IFERROR(INDEX(Backlog!$A$2:$A$300,MATCH("Blocked|18",Backlog!$AL$2:$AL$300,0))&" · "&INDEX(Backlog!$D$2:$D$300,MATCH("Blocked|18",Backlog!$AL$2:$AL$300,0)),"") | F23: =IFERROR(INDEX(Backlog!$A$2:$A$300,MATCH("Done|18",Backlog!$AL$2:$AL$300,0))&" · "&INDEX(Backlog!$D$2:$D$300,MATCH("Done|18",Backlog!$AL$2:$AL$300,0)),"")
B24: =IFERROR(INDEX(Backlog!$A$2:$A$300,MATCH("To Do|19",Backlog!$AL$2:$AL$300,0))&" · "&INDEX(Backlog!$D$2:$D$300,MATCH("To Do|19",Backlog!$AL$2:$AL$300,0)),"") | C24: =IFERROR(INDEX(Backlog!$A$2:$A$300,MATCH("In Progress|19",Backlog!$AL$2:$AL$300,0))&" · "&INDEX(Backlog!$D$2:$D$300,MATCH("In Progress|19",Backlog!$AL$2:$AL$300,0)),"") | D24: =IFERROR(INDEX(Backlog!$A$2:$A$300,MATCH("In Review|19",Backlog!$AL$2:$AL$300,0))&" · "&INDEX(Backlog!$D$2:$D$300,MATCH("In Review|19",Backlog!$AL$2:$AL$300,0)),"") | E24: =IFERROR(INDEX(Backlog!$A$2:$A$300,MATCH("Blocked|19",Backlog!$AL$2:$AL$300,0))&" · "&INDEX(Backlog!$D$2:$D$300,MATCH("Blocked|19",Backlog!$AL$2:$AL$300,0)),"") | F24: =IFERROR(INDEX(Backlog!$A$2:$A$300,MATCH("Done|19",Backlog!$AL$2:$AL$300,0))&" · "&INDEX(Backlog!$D$2:$D$300,MATCH("Done|19",Backlog!$AL$2:$AL$300,0)),"")
B25: =IFERROR(INDEX(Backlog!$A$2:$A$300,MATCH("To Do|20",Backlog!$AL$2:$AL$300,0))&" · "&INDEX(Backlog!$D$2:$D$300,MATCH("To Do|20",Backlog!$AL$2:$AL$300,0)),"") | C25: =IFERROR(INDEX(Backlog!$A$2:$A$300,MATCH("In Progress|20",Backlog!$AL$2:$AL$300,0))&" · "&INDEX(Backlog!$D$2:$D$300,MATCH("In Progress|20",Backlog!$AL$2:$AL$300,0)),"") | D25: =IFERROR(INDEX(Backlog!$A$2:$A$300,MATCH("In Review|20",Backlog!$AL$2:$AL$300,0))&" · "&INDEX(Backlog!$D$2:$D$300,MATCH("In Review|20",Backlog!$AL$2:$AL$300,0)),"") | E25: =IFERROR(INDEX(Backlog!$A$2:$A$300,MATCH("Blocked|20",Backlog!$AL$2:$AL$300,0))&" · "&INDEX(Backlog!$D$2:$D$300,MATCH("Blocked|20",Backlog!$AL$2:$AL$300,0)),"") | F25: =IFERROR(INDEX(Backlog!$A$2:$A$300,MATCH("Done|20",Backlog!$AL$2:$AL$300,0))&" · "&INDEX(Backlog!$D$2:$D$300,MATCH("Done|20",Backlog!$AL$2:$AL$300,0)),"")
B26: =IFERROR(INDEX(Backlog!$A$2:$A$300,MATCH("To Do|21",Backlog!$AL$2:$AL$300,0))&" · "&INDEX(Backlog!$D$2:$D$300,MATCH("To Do|21",Backlog!$AL$2:$AL$300,0)),"") | C26: =IFERROR(INDEX(Backlog!$A$2:$A$300,MATCH("In Progress|21",Backlog!$AL$2:$AL$300,0))&" · "&INDEX(Backlog!$D$2:$D$300,MATCH("In Progress|21",Backlog!$AL$2:$AL$300,0)),"") | D26: =IFERROR(INDEX(Backlog!$A$2:$A$300,MATCH("In Review|21",Backlog!$AL$2:$AL$300,0))&" · "&INDEX(Backlog!$D$2:$D$300,MATCH("In Review|21",Backlog!$AL$2:$AL$300,0)),"") | E26: =IFERROR(INDEX(Backlog!$A$2:$A$300,MATCH("Blocked|21",Backlog!$AL$2:$AL$300,0))&" · "&INDEX(Backlog!$D$2:$D$300,MATCH("Blocked|21",Backlog!$AL$2:$AL$300,0)),"") | F26: =IFERROR(INDEX(Backlog!$A$2:$A$300,MATCH("Done|21",Backlog!$AL$2:$AL$300,0))&" · "&INDEX(Backlog!$D$2:$D$300,MATCH("Done|21",Backlog!$AL$2:$AL$300,0)),"")
B27: =IFERROR(INDEX(Backlog!$A$2:$A$300,MATCH("To Do|22",Backlog!$AL$2:$AL$300,0))&" · "&INDEX(Backlog!$D$2:$D$300,MATCH("To Do|22",Backlog!$AL$2:$AL$300,0)),"") | C27: =IFERROR(INDEX(Backlog!$A$2:$A$300,MATCH("In Progress|22",Backlog!$AL$2:$AL$300,0))&" · "&INDEX(Backlog!$D$2:$D$300,MATCH("In Progress|22",Backlog!$AL$2:$AL$300,0)),"") | D27: =IFERROR(INDEX(Backlog!$A$2:$A$300,MATCH("In Review|22",Backlog!$AL$2:$AL$300,0))&" · "&INDEX(Backlog!$D$2:$D$300,MATCH("In Review|22",Backlog!$AL$2:$AL$300,0)),"") | E27: =IFERROR(INDEX(Backlog!$A$2:$A$300,MATCH("Blocked|22",Backlog!$AL$2:$AL$300,0))&" · "&INDEX(Backlog!$D$2:$D$300,MATCH("Blocked|22",Backlog!$AL$2:$AL$300,0)),"") | F27: =IFERROR(INDEX(Backlog!$A$2:$A$300,MATCH("Done|22",Backlog!$AL$2:$AL$300,0))&" · "&INDEX(Backlog!$D$2:$D$300,MATCH("Done|22",Backlog!$AL$2:$AL$300,0)),"")
B28: =IFERROR(INDEX(Backlog!$A$2:$A$300,MATCH("To Do|23",Backlog!$AL$2:$AL$300,0))&" · "&INDEX(Backlog!$D$2:$D$300,MATCH("To Do|23",Backlog!$AL$2:$AL$300,0)),"") | C28: =IFERROR(INDEX(Backlog!$A$2:$A$300,MATCH("In Progress|23",Backlog!$AL$2:$AL$300,0))&" · "&INDEX(Backlog!$D$2:$D$300,MATCH("In Progress|23",Backlog!$AL$2:$AL$300,0)),"") | D28: =IFERROR(INDEX(Backlog!$A$2:$A$300,MATCH("In Review|23",Backlog!$AL$2:$AL$300,0))&" · "&INDEX(Backlog!$D$2:$D$300,MATCH("In Review|23",Backlog!$AL$2:$AL$300,0)),"") | E28: =IFERROR(INDEX(Backlog!$A$2:$A$300,MATCH("Blocked|23",Backlog!$AL$2:$AL$300,0))&" · "&INDEX(Backlog!$D$2:$D$300,MATCH("Blocked|23",Backlog!$AL$2:$AL$300,0)),"") | F28: =IFERROR(INDEX(Backlog!$A$2:$A$300,MATCH("Done|23",Backlog!$AL$2:$AL$300,0))&" · "&INDEX(Backlog!$D$2:$D$300,MATCH("Done|23",Backlog!$AL$2:$AL$300,0)),"")
B29: =IFERROR(INDEX(Backlog!$A$2:$A$300,MATCH("To Do|24",Backlog!$AL$2:$AL$300,0))&" · "&INDEX(Backlog!$D$2:$D$300,MATCH("To Do|24",Backlog!$AL$2:$AL$300,0)),"") | C29: =IFERROR(INDEX(Backlog!$A$2:$A$300,MATCH("In Progress|24",Backlog!$AL$2:$AL$300,0))&" · "&INDEX(Backlog!$D$2:$D$300,MATCH("In Progress|24",Backlog!$AL$2:$AL$300,0)),"") | D29: =IFERROR(INDEX(Backlog!$A$2:$A$300,MATCH("In Review|24",Backlog!$AL$2:$AL$300,0))&" · "&INDEX(Backlog!$D$2:$D$300,MATCH("In Review|24",Backlog!$AL$2:$AL$300,0)),"") | E29: =IFERROR(INDEX(Backlog!$A$2:$A$300,MATCH("Blocked|24",Backlog!$AL$2:$AL$300,0))&" · "&INDEX(Backlog!$D$2:$D$300,MATCH("Blocked|24",Backlog!$AL$2:$AL$300,0)),"") | F29: =IFERROR(INDEX(Backlog!$A$2:$A$300,MATCH("Done|24",Backlog!$AL$2:$AL$300,0))&" · "&INDEX(Backlog!$D$2:$D$300,MATCH("Done|24",Backlog!$AL$2:$AL$300,0)),"")
B30: =IFERROR(INDEX(Backlog!$A$2:$A$300,MATCH("To Do|25",Backlog!$AL$2:$AL$300,0))&" · "&INDEX(Backlog!$D$2:$D$300,MATCH("To Do|25",Backlog!$AL$2:$AL$300,0)),"") | C30: =IFERROR(INDEX(Backlog!$A$2:$A$300,MATCH("In Progress|25",Backlog!$AL$2:$AL$300,0))&" · "&INDEX(Backlog!$D$2:$D$300,MATCH("In Progress|25",Backlog!$AL$2:$AL$300,0)),"") | D30: =IFERROR(INDEX(Backlog!$A$2:$A$300,MATCH("In Review|25",Backlog!$AL$2:$AL$300,0))&" · "&INDEX(Backlog!$D$2:$D$300,MATCH("In Review|25",Backlog!$AL$2:$AL$300,0)),"") | E30: =IFERROR(INDEX(Backlog!$A$2:$A$300,MATCH("Blocked|25",Backlog!$AL$2:$AL$300,0))&" · "&INDEX(Backlog!$D$2:$D$300,MATCH("Blocked|25",Backlog!$AL$2:$AL$300,0)),"") | F30: =IFERROR(INDEX(Backlog!$A$2:$A$300,MATCH("Done|25",Backlog!$AL$2:$AL$300,0))&" · "&INDEX(Backlog!$D$2:$D$300,MATCH("Done|25",Backlog!$AL$2:$AL$300,0)),"")
B31: =IFERROR(INDEX(Backlog!$A$2:$A$300,MATCH("To Do|26",Backlog!$AL$2:$AL$300,0))&" · "&INDEX(Backlog!$D$2:$D$300,MATCH("To Do|26",Backlog!$AL$2:$AL$300,0)),"") | C31: =IFERROR(INDEX(Backlog!$A$2:$A$300,MATCH("In Progress|26",Backlog!$AL$2:$AL$300,0))&" · "&INDEX(Backlog!$D$2:$D$300,MATCH("In Progress|26",Backlog!$AL$2:$AL$300,0)),"") | D31: =IFERROR(INDEX(Backlog!$A$2:$A$300,MATCH("In Review|26",Backlog!$AL$2:$AL$300,0))&" · "&INDEX(Backlog!$D$2:$D$300,MATCH("In Review|26",Backlog!$AL$2:$AL$300,0)),"") | E31: =IFERROR(INDEX(Backlog!$A$2:$A$300,MATCH("Blocked|26",Backlog!$AL$2:$AL$300,0))&" · "&INDEX(Backlog!$D$2:$D$300,MATCH("Blocked|26",Backlog!$AL$2:$AL$300,0)),"") | F31: =IFERROR(INDEX(Backlog!$A$2:$A$300,MATCH("Done|26",Backlog!$AL$2:$AL$300,0))&" · "&INDEX(Backlog!$D$2:$D$300,MATCH("Done|26",Backlog!$AL$2:$AL$300,0)),"")
B32: =IFERROR(INDEX(Backlog!$A$2:$A$300,MATCH("To Do|27",Backlog!$AL$2:$AL$300,0))&" · "&INDEX(Backlog!$D$2:$D$300,MATCH("To Do|27",Backlog!$AL$2:$AL$300,0)),"") | C32: =IFERROR(INDEX(Backlog!$A$2:$A$300,MATCH("In Progress|27",Backlog!$AL$2:$AL$300,0))&" · "&INDEX(Backlog!$D$2:$D$300,MATCH("In Progress|27",Backlog!$AL$2:$AL$300,0)),"") | D32: =IFERROR(INDEX(Backlog!$A$2:$A$300,MATCH("In Review|27",Backlog!$AL$2:$AL$300,0))&" · "&INDEX(Backlog!$D$2:$D$300,MATCH("In Review|27",Backlog!$AL$2:$AL$300,0)),"") | E32: =IFERROR(INDEX(Backlog!$A$2:$A$300,MATCH("Blocked|27",Backlog!$AL$2:$AL$300,0))&" · "&INDEX(Backlog!$D$2:$D$300,MATCH("Blocked|27",Backlog!$AL$2:$AL$300,0)),"") | F32: =IFERROR(INDEX(Backlog!$A$2:$A$300,MATCH("Done|27",Backlog!$AL$2:$AL$300,0))&" · "&INDEX(Backlog!$D$2:$D$300,MATCH("Done|27",Backlog!$AL$2:$AL$300,0)),"")
B33: =IFERROR(INDEX(Backlog!$A$2:$A$300,MATCH("To Do|28",Backlog!$AL$2:$AL$300,0))&" · "&INDEX(Backlog!$D$2:$D$300,MATCH("To Do|28",Backlog!$AL$2:$AL$300,0)),"") | C33: =IFERROR(INDEX(Backlog!$A$2:$A$300,MATCH("In Progress|28",Backlog!$AL$2:$AL$300,0))&" · "&INDEX(Backlog!$D$2:$D$300,MATCH("In Progress|28",Backlog!$AL$2:$AL$300,0)),"") | D33: =IFERROR(INDEX(Backlog!$A$2:$A$300,MATCH("In Review|28",Backlog!$AL$2:$AL$300,0))&" · "&INDEX(Backlog!$D$2:$D$300,MATCH("In Review|28",Backlog!$AL$2:$AL$300,0)),"") | E33: =IFERROR(INDEX(Backlog!$A$2:$A$300,MATCH("Blocked|28",Backlog!$AL$2:$AL$300,0))&" · "&INDEX(Backlog!$D$2:$D$300,MATCH("Blocked|28",Backlog!$AL$2:$AL$300,0)),"") | F33: =IFERROR(INDEX(Backlog!$A$2:$A$300,MATCH("Done|28",Backlog!$AL$2:$AL$300,0))&" · "&INDEX(Backlog!$D$2:$D$300,MATCH("Done|28",Backlog!$AL$2:$AL$300,0)),"")
B34: =IFERROR(INDEX(Backlog!$A$2:$A$300,MATCH("To Do|29",Backlog!$AL$2:$AL$300,0))&" · "&INDEX(Backlog!$D$2:$D$300,MATCH("To Do|29",Backlog!$AL$2:$AL$300,0)),"") | C34: =IFERROR(INDEX(Backlog!$A$2:$A$300,MATCH("In Progress|29",Backlog!$AL$2:$AL$300,0))&" · "&INDEX(Backlog!$D$2:$D$300,MATCH("In Progress|29",Backlog!$AL$2:$AL$300,0)),"") | D34: =IFERROR(INDEX(Backlog!$A$2:$A$300,MATCH("In Review|29",Backlog!$AL$2:$AL$300,0))&" · "&INDEX(Backlog!$D$2:$D$300,MATCH("In Review|29",Backlog!$AL$2:$AL$300,0)),"") | E34: =IFERROR(INDEX(Backlog!$A$2:$A$300,MATCH("Blocked|29",Backlog!$AL$2:$AL$300,0))&" · "&INDEX(Backlog!$D$2:$D$300,MATCH("Blocked|29",Backlog!$AL$2:$AL$300,0)),"") | F34: =IFERROR(INDEX(Backlog!$A$2:$A$300,MATCH("Done|29",Backlog!$AL$2:$AL$300,0))&" · "&INDEX(Backlog!$D$2:$D$300,MATCH("Done|29",Backlog!$AL$2:$AL$300,0)),"")
B35: =IFERROR(INDEX(Backlog!$A$2:$A$300,MATCH("To Do|30",Backlog!$AL$2:$AL$300,0))&" · "&INDEX(Backlog!$D$2:$D$300,MATCH("To Do|30",Backlog!$AL$2:$AL$300,0)),"") | C35: =IFERROR(INDEX(Backlog!$A$2:$A$300,MATCH("In Progress|30",Backlog!$AL$2:$AL$300,0))&" · "&INDEX(Backlog!$D$2:$D$300,MATCH("In Progress|30",Backlog!$AL$2:$AL$300,0)),"") | D35: =IFERROR(INDEX(Backlog!$A$2:$A$300,MATCH("In Review|30",Backlog!$AL$2:$AL$300,0))&" · "&INDEX(Backlog!$D$2:$D$300,MATCH("In Review|30",Backlog!$AL$2:$AL$300,0)),"") | E35: =IFERROR(INDEX(Backlog!$A$2:$A$300,MATCH("Blocked|30",Backlog!$AL$2:$AL$300,0))&" · "&INDEX(Backlog!$D$2:$D$300,MATCH("Blocked|30",Backlog!$AL$2:$AL$300,0)),"") | F35: =IFERROR(INDEX(Backlog!$A$2:$A$300,MATCH("Done|30",Backlog!$AL$2:$AL$300,0))&" · "&INDEX(Backlog!$D$2:$D$300,MATCH("Done|30",Backlog!$AL$2:$AL$300,0)),"")
B36: =IFERROR(INDEX(Backlog!$A$2:$A$300,MATCH("To Do|31",Backlog!$AL$2:$AL$300,0))&" · "&INDEX(Backlog!$D$2:$D$300,MATCH("To Do|31",Backlog!$AL$2:$AL$300,0)),"") | C36: =IFERROR(INDEX(Backlog!$A$2:$A$300,MATCH("In Progress|31",Backlog!$AL$2:$AL$300,0))&" · "&INDEX(Backlog!$D$2:$D$300,MATCH("In Progress|31",Backlog!$AL$2:$AL$300,0)),"") | D36: =IFERROR(INDEX(Backlog!$A$2:$A$300,MATCH("In Review|31",Backlog!$AL$2:$AL$300,0))&" · "&INDEX(Backlog!$D$2:$D$300,MATCH("In Review|31",Backlog!$AL$2:$AL$300,0)),"") | E36: =IFERROR(INDEX(Backlog!$A$2:$A$300,MATCH("Blocked|31",Backlog!$AL$2:$AL$300,0))&" · "&INDEX(Backlog!$D$2:$D$300,MATCH("Blocked|31",Backlog!$AL$2:$AL$300,0)),"") | F36: =IFERROR(INDEX(Backlog!$A$2:$A$300,MATCH("Done|31",Backlog!$AL$2:$AL$300,0))&" · "&INDEX(Backlog!$D$2:$D$300,MATCH("Done|31",Backlog!$AL$2:$AL$300,0)),"")
B37: =IFERROR(INDEX(Backlog!$A$2:$A$300,MATCH("To Do|32",Backlog!$AL$2:$AL$300,0))&" · "&INDEX(Backlog!$D$2:$D$300,MATCH("To Do|32",Backlog!$AL$2:$AL$300,0)),"") | C37: =IFERROR(INDEX(Backlog!$A$2:$A$300,MATCH("In Progress|32",Backlog!$AL$2:$AL$300,0))&" · "&INDEX(Backlog!$D$2:$D$300,MATCH("In Progress|32",Backlog!$AL$2:$AL$300,0)),"") | D37: =IFERROR(INDEX(Backlog!$A$2:$A$300,MATCH("In Review|32",Backlog!$AL$2:$AL$300,0))&" · "&INDEX(Backlog!$D$2:$D$300,MATCH("In Review|32",Backlog!$AL$2:$AL$300,0)),"") | E37: =IFERROR(INDEX(Backlog!$A$2:$A$300,MATCH("Blocked|32",Backlog!$AL$2:$AL$300,0))&" · "&INDEX(Backlog!$D$2:$D$300,MATCH("Blocked|32",Backlog!$AL$2:$AL$300,0)),"") | F37: =IFERROR(INDEX(Backlog!$A$2:$A$300,MATCH("Done|32",Backlog!$AL$2:$AL$300,0))&" · "&INDEX(Backlog!$D$2:$D$300,MATCH("Done|32",Backlog!$AL$2:$AL$300,0)),"")
B38: =IFERROR(INDEX(Backlog!$A$2:$A$300,MATCH("To Do|33",Backlog!$AL$2:$AL$300,0))&" · "&INDEX(Backlog!$D$2:$D$300,MATCH("To Do|33",Backlog!$AL$2:$AL$300,0)),"") | C38: =IFERROR(INDEX(Backlog!$A$2:$A$300,MATCH("In Progress|33",Backlog!$AL$2:$AL$300,0))&" · "&INDEX(Backlog!$D$2:$D$300,MATCH("In Progress|33",Backlog!$AL$2:$AL$300,0)),"") | D38: =IFERROR(INDEX(Backlog!$A$2:$A$300,MATCH("In Review|33",Backlog!$AL$2:$AL$300,0))&" · "&INDEX(Backlog!$D$2:$D$300,MATCH("In Review|33",Backlog!$AL$2:$AL$300,0)),"") | E38: =IFERROR(INDEX(Backlog!$A$2:$A$300,MATCH("Blocked|33",Backlog!$AL$2:$AL$300,0))&" · "&INDEX(Backlog!$D$2:$D$300,MATCH("Blocked|33",Backlog!$AL$2:$AL$300,0)),"") | F38: =IFERROR(INDEX(Backlog!$A$2:$A$300,MATCH("Done|33",Backlog!$AL$2:$AL$300,0))&" · "&INDEX(Backlog!$D$2:$D$300,MATCH("Done|33",Backlog!$AL$2:$AL$300,0)),"")
B39: =IFERROR(INDEX(Backlog!$A$2:$A$300,MATCH("To Do|34",Backlog!$AL$2:$AL$300,0))&" · "&INDEX(Backlog!$D$2:$D$300,MATCH("To Do|34",Backlog!$AL$2:$AL$300,0)),"") | C39: =IFERROR(INDEX(Backlog!$A$2:$A$300,MATCH("In Progress|34",Backlog!$AL$2:$AL$300,0))&" · "&INDEX(Backlog!$D$2:$D$300,MATCH("In Progress|34",Backlog!$AL$2:$AL$300,0)),"") | D39: =IFERROR(INDEX(Backlog!$A$2:$A$300,MATCH("In Review|34",Backlog!$AL$2:$AL$300,0))&" · "&INDEX(Backlog!$D$2:$D$300,MATCH("In Review|34",Backlog!$AL$2:$AL$300,0)),"") | E39: =IFERROR(INDEX(Backlog!$A$2:$A$300,MATCH("Blocked|34",Backlog!$AL$2:$AL$300,0))&" · "&INDEX(Backlog!$D$2:$D$300,MATCH("Blocked|34",Backlog!$AL$2:$AL$300,0)),"") | F39: =IFERROR(INDEX(Backlog!$A$2:$A$300,MATCH("Done|34",Backlog!$AL$2:$AL$300,0))&" · "&INDEX(Backlog!$D$2:$D$300,MATCH("Done|34",Backlog!$AL$2:$AL$300,0)),"")
B40: =IFERROR(INDEX(Backlog!$A$2:$A$300,MATCH("To Do|35",Backlog!$AL$2:$AL$300,0))&" · "&INDEX(Backlog!$D$2:$D$300,MATCH("To Do|35",Backlog!$AL$2:$AL$300,0)),"") | C40: =IFERROR(INDEX(Backlog!$A$2:$A$300,MATCH("In Progress|35",Backlog!$AL$2:$AL$300,0))&" · "&INDEX(Backlog!$D$2:$D$300,MATCH("In Progress|35",Backlog!$AL$2:$AL$300,0)),"") | D40: =IFERROR(INDEX(Backlog!$A$2:$A$300,MATCH("In Review|35",Backlog!$AL$2:$AL$300,0))&" · "&INDEX(Backlog!$D$2:$D$300,MATCH("In Review|35",Backlog!$AL$2:$AL$300,0)),"") | E40: =IFERROR(INDEX(Backlog!$A$2:$A$300,MATCH("Blocked|35",Backlog!$AL$2:$AL$300,0))&" · "&INDEX(Backlog!$D$2:$D$300,MATCH("Blocked|35",Backlog!$AL$2:$AL$300,0)),"") | F40: =IFERROR(INDEX(Backlog!$A$2:$A$300,MATCH("Done|35",Backlog!$AL$2:$AL$300,0))&" · "&INDEX(Backlog!$D$2:$D$300,MATCH("Done|35",Backlog!$AL$2:$AL$300,0)),"")
B41: =IFERROR(INDEX(Backlog!$A$2:$A$300,MATCH("To Do|36",Backlog!$AL$2:$AL$300,0))&" · "&INDEX(Backlog!$D$2:$D$300,MATCH("To Do|36",Backlog!$AL$2:$AL$300,0)),"") | C41: =IFERROR(INDEX(Backlog!$A$2:$A$300,MATCH("In Progress|36",Backlog!$AL$2:$AL$300,0))&" · "&INDEX(Backlog!$D$2:$D$300,MATCH("In Progress|36",Backlog!$AL$2:$AL$300,0)),"") | D41: =IFERROR(INDEX(Backlog!$A$2:$A$300,MATCH("In Review|36",Backlog!$AL$2:$AL$300,0))&" · "&INDEX(Backlog!$D$2:$D$300,MATCH("In Review|36",Backlog!$AL$2:$AL$300,0)),"") | E41: =IFERROR(INDEX(Backlog!$A$2:$A$300,MATCH("Blocked|36",Backlog!$AL$2:$AL$300,0))&" · "&INDEX(Backlog!$D$2:$D$300,MATCH("Blocked|36",Backlog!$AL$2:$AL$300,0)),"") | F41: =IFERROR(INDEX(Backlog!$A$2:$A$300,MATCH("Done|36",Backlog!$AL$2:$AL$300,0))&" · "&INDEX(Backlog!$D$2:$D$300,MATCH("Done|36",Backlog!$AL$2:$AL$300,0)),"")
...

Sheet Dashboard
A1: Dashboard
A2: All figures are formulas over Backlog, Screens, Test Cases and Translations.
A4: Key figures
A5: Total tickets | B5: =COUNTA(Backlog!$A$2:$A$300)
A6: Total story points | B6: =SUM(Backlog!$U$2:$U$300)
A7: Blocked tickets | B7: =COUNTIF(Backlog!$AD$2:$AD$300,"Blocked")
A8: Awaiting human review (In Review) | B8: =COUNTIF(Backlog!$AD$2:$AD$300,"In Review")
A9: Awaiting merge (Git-PR-CI) | B9: =COUNTIF('Git-PR-CI'!$M$2:$M$300,"Pending")
A10: Failed checks (Git-PR-CI) | B10: =COUNTIF('Git-PR-CI'!$E$2:$L$300,"Fail")
A11: Open dependencies (not Done, has deps) | B11: =COUNTIFS(Backlog!$A$2:$A$300,"<>",Backlog!$AD$2:$AD$300,"<>Done",Backlog!$N$2:$N$300,"<>None")
A12: Screens with design missing | B12: =COUNTIF(Screens!$P$2:$P$100,"Design Missing")
A13: Screens not yet verified | B13: =COUNTA(Screens!$B$2:$B$100)-COUNTIF(Screens!$Q$2:$Q$100,"Verified")
A14: Test cases not passing | B14: =COUNTA('Test Cases'!$A$2:$A$300)-COUNTIF('Test Cases'!$N$2:$N$300,"Pass")
A15: Kannada strings missing | B15: =COUNTIF(Translations!$G$2:$G$500,"Missing")
A16: Kannada strings awaiting native review | B16: =COUNTIF(Translations!$G$2:$G$500,"Needs native review")+COUNTIF(Translations!$G$2:$G$500,"Draft")
A18: By status | B18: Tickets | C18: Points | E18: By priority | F18: Tickets | G18: Points | I18: By MoSCoW | J18: Tickets | K18: Points
A19: To Do | B19: =COUNTIF(Backlog!$AD$2:$AD$300,"To Do") | C19: =SUMIF(Backlog!$AD$2:$AD$300,"To Do",Backlog!$U$2:$U$300) | E19: Highest | F19: =COUNTIF(Backlog!$H$2:$H$300,"Highest") | G19: =SUMIF(Backlog!$H$2:$H$300,"Highest",Backlog!$U$2:$U$300) | I19: Must | J19: =COUNTIF(Backlog!$I$2:$I$300,"Must") | K19: =SUMIF(Backlog!$I$2:$I$300,"Must",Backlog!$U$2:$U$300)
A20: In Progress | B20: =COUNTIF(Backlog!$AD$2:$AD$300,"In Progress") | C20: =SUMIF(Backlog!$AD$2:$AD$300,"In Progress",Backlog!$U$2:$U$300) | E20: High | F20: =COUNTIF(Backlog!$H$2:$H$300,"High") | G20: =SUMIF(Backlog!$H$2:$H$300,"High",Backlog!$U$2:$U$300) | I20: Should | J20: =COUNTIF(Backlog!$I$2:$I$300,"Should") | K20: =SUMIF(Backlog!$I$2:$I$300,"Should",Backlog!$U$2:$U$300)
A21: In Review | B21: =COUNTIF(Backlog!$AD$2:$AD$300,"In Review") | C21: =SUMIF(Backlog!$AD$2:$AD$300,"In Review",Backlog!$U$2:$U$300) | E21: Medium | F21: =COUNTIF(Backlog!$H$2:$H$300,"Medium") | G21: =SUMIF(Backlog!$H$2:$H$300,"Medium",Backlog!$U$2:$U$300) | I21: Could | J21: =COUNTIF(Backlog!$I$2:$I$300,"Could") | K21: =SUMIF(Backlog!$I$2:$I$300,"Could",Backlog!$U$2:$U$300)
A22: Blocked | B22: =COUNTIF(Backlog!$AD$2:$AD$300,"Blocked") | C22: =SUMIF(Backlog!$AD$2:$AD$300,"Blocked",Backlog!$U$2:$U$300) | E22: Low | F22: =COUNTIF(Backlog!$H$2:$H$300,"Low") | G22: =SUMIF(Backlog!$H$2:$H$300,"Low",Backlog!$U$2:$U$300) | I22: Won't | J22: =COUNTIF(Backlog!$I$2:$I$300,"Won't") | K22: =SUMIF(Backlog!$I$2:$I$300,"Won't",Backlog!$U$2:$U$300)
A23: Done | B23: =COUNTIF(Backlog!$AD$2:$AD$300,"Done") | C23: =SUMIF(Backlog!$AD$2:$AD$300,"Done",Backlog!$U$2:$U$300)
A24: Needs Clarification | B24: =COUNTIF(Backlog!$AD$2:$AD$300,"Needs Clarification") | C24: =SUMIF(Backlog!$AD$2:$AD$300,"Needs Clarification",Backlog!$U$2:$U$300)
A26: By phase | B26: Tickets | C26: Points | E26: By type | F26: Tickets | G26: Points | I26: By Kannada status | J26: Tickets | K26: Points
A27: P0 | B27: =COUNTIF(Backlog!$J$2:$J$300,"P0") | C27: =SUMIF(Backlog!$J$2:$J$300,"P0",Backlog!$U$2:$U$300) | E27: Story | F27: =COUNTIF(Backlog!$B$2:$B$300,"Story") | G27: =SUMIF(Backlog!$B$2:$B$300,"Story",Backlog!$U$2:$U$300) | I27: N/A | J27: =COUNTIF(Backlog!$AI$2:$AI$300,"N/A") | K27: =SUMIF(Backlog!$AI$2:$AI$300,"N/A",Backlog!$U$2:$U$300)
A28: P1 | B28: =COUNTIF(Backlog!$J$2:$J$300,"P1") | C28: =SUMIF(Backlog!$J$2:$J$300,"P1",Backlog!$U$2:$U$300) | E28: Task | F28: =COUNTIF(Backlog!$B$2:$B$300,"Task") | G28: =SUMIF(Backlog!$B$2:$B$300,"Task",Backlog!$U$2:$U$300) | I28: Missing | J28: =COUNTIF(Backlog!$AI$2:$AI$300,"Missing") | K28: =SUMIF(Backlog!$AI$2:$AI$300,"Missing",Backlog!$U$2:$U$300)
A29: P2 | B29: =COUNTIF(Backlog!$J$2:$J$300,"P2") | C29: =SUMIF(Backlog!$J$2:$J$300,"P2",Backlog!$U$2:$U$300) | E29: Bug | F29: =COUNTIF(Backlog!$B$2:$B$300,"Bug") | G29: =SUMIF(Backlog!$B$2:$B$300,"Bug",Backlog!$U$2:$U$300) | I29: Draft | J29: =COUNTIF(Backlog!$AI$2:$AI$300,"Draft") | K29: =SUMIF(Backlog!$AI$2:$AI$300,"Draft",Backlog!$U$2:$U$300)
A30: P3 | B30: =COUNTIF(Backlog!$J$2:$J$300,"P3") | C30: =SUMIF(Backlog!$J$2:$J$300,"P3",Backlog!$U$2:$U$300) | I30: Needs native review | J30: =COUNTIF(Backlog!$AI$2:$AI$300,"Needs native review") | K30: =SUMIF(Backlog!$AI$2:$AI$300,"Needs native review",Backlog!$U$2:$U$300)
A31: P4 | B31: =COUNTIF(Backlog!$J$2:$J$300,"P4") | C31: =SUMIF(Backlog!$J$2:$J$300,"P4",Backlog!$U$2:$U$300) | I31: Approved | J31: =COUNTIF(Backlog!$AI$2:$AI$300,"Approved") | K31: =SUMIF(Backlog!$AI$2:$AI$300,"Approved",Backlog!$U$2:$U$300)
A32: P5 | B32: =COUNTIF(Backlog!$J$2:$J$300,"P5") | C32: =SUMIF(Backlog!$J$2:$J$300,"P5",Backlog!$U$2:$U$300)
A33: P6 | B33: =COUNTIF(Backlog!$J$2:$J$300,"P6") | C33: =SUMIF(Backlog!$J$2:$J$300,"P6",Backlog!$U$2:$U$300)
A34: P7 | B34: =COUNTIF(Backlog!$J$2:$J$300,"P7") | C34: =SUMIF(Backlog!$J$2:$J$300,"P7",Backlog!$U$2:$U$300)
A35: P8 | B35: =COUNTIF(Backlog!$J$2:$J$300,"P8") | C35: =SUMIF(Backlog!$J$2:$J$300,"P8",Backlog!$U$2:$U$300)
A37: By epic | B37: Tickets | C37: Points
A38: LS-EPIC-01 | B38: =COUNTIF(Backlog!$C$2:$C$300,"LS-EPIC-01") | C38: =SUMIF(Backlog!$C$2:$C$300,"LS-EPIC-01",Backlog!$U$2:$U$300)
A39: LS-EPIC-02 | B39: =COUNTIF(Backlog!$C$2:$C$300,"LS-EPIC-02") | C39: =SUMIF(Backlog!$C$2:$C$300,"LS-EPIC-02",Backlog!$U$2:$U$300)
A40: LS-EPIC-03 | B40: =COUNTIF(Backlog!$C$2:$C$300,"LS-EPIC-03") | C40: =SUMIF(Backlog!$C$2:$C$300,"LS-EPIC-03",Backlog!$U$2:$U$300)
A41: LS-EPIC-04 | B41: =COUNTIF(Backlog!$C$2:$C$300,"LS-EPIC-04") | C41: =SUMIF(Backlog!$C$2:$C$300,"LS-EPIC-04",Backlog!$U$2:$U$300)
A42: LS-EPIC-05 | B42: =COUNTIF(Backlog!$C$2:$C$300,"LS-EPIC-05") | C42: =SUMIF(Backlog!$C$2:$C$300,"LS-EPIC-05",Backlog!$U$2:$U$300)
A43: LS-EPIC-06 | B43: =COUNTIF(Backlog!$C$2:$C$300,"LS-EPIC-06") | C43: =SUMIF(Backlog!$C$2:$C$300,"LS-EPIC-06",Backlog!$U$2:$U$300)
A44: LS-EPIC-07 | B44: =COUNTIF(Backlog!$C$2:$C$300,"LS-EPIC-07") | C44: =SUMIF(Backlog!$C$2:$C$300,"LS-EPIC-07",Backlog!$U$2:$U$300)
...

Sheet Backlog
A1: Issue Key | B1: Issue Type | C1: Epic Link | D1: Summary | E1: Description | F1: User Story | G1: Business Value | H1: Priority | I1: MoSCoW | J1: Phase | K1: Component/Module | L1: Screen ID | M1: Figma Frame Reference | N1: Dependencies | O1: Blocks / Blocked By | P1: Acceptance Criteria | Q1: Definition of Done | R1: Implementation Notes | S1: Required Tests | T1: Test Evidence | U1: Estimate (Story Points) | V1: Estimated Complexity | W1: Risk | X1: Agent Role | Y1: Parallelizable | Z1: Shared File Conflict Risk | AA1: Branch Name | AB1: Pull Request Link | AC1: Assignee | AD1: Status | AE1: Reviewer | AF1: Approval Status | AG1: Actual Result | AH1: Localization Impact | AI1: Kannada Translation Status | AJ1: Notes | AK1: Requirement IDs | AL1: Board Key (formula)
A2: LS-001 | B2: Task | C2: LS-EPIC-01 | D2: Read-only repository & toolchain discovery | E2: Inspect local repo, git state, branches, Gradle/AGP/Kotlin/JDK/SDK versions, modules, manifests, tests, CI, existing docs, cross-platform readiness (gradlew/gradlew.bat, .gitattributes, encodings). No file changes. | F2: – | G2: Delivery clarity – avoids rework | H2: Highest | I2: Must | J2: P0 | K2: Repo / tooling | L2: – | M2: – | N2: None | O2: Blocks: LS-003, LS-005, LS-007, LS-008, LS-030, LS-131 Blocked by: – | P2: 1. Discovery report covers all 17 items of master prompt §2.2 2. Zero files changed (git status clean before/after) 3. Toolchain versions and compatibility issues listed 4. Report ends with Approval gate question | Q2: Std DoD: AC met · no hardcoded strings/colours/dims/config · EN + KN strings present · unit/UI tests pass · lint + translation check pass · screenshots EN/KN attached (UI) · docs updated · human PR review & merge · post-merge verified | R2: Use tokens, string resources (EN+KN) and AppConfig only. | S2: N/A (read-only) – verify `git status` unchanged | T2: Read-only: git/GitHub inspection, Figma whoami, network probes | U2: 3 | V2: Medium | W2: Low | X2: Orchestrator | Y2: Yes | Z2: Low | AA2: feature/LS-001-read-only-repository-toolchain-discovery | AD2: Done | AE2: Project owner (human) | AF2: Approval A — report delivered | AG2: P0 assessment delivered 29 Oct 2026 (Claude Doc "LittleStory — P0 Discovery Assessment"): repo docs-only, default branch misconfigured, Figma Make not readable by agents, cloud workspace cannot reach dl.google.com. | AH2: None | AI2: N/A | AJ2: Run on owner's machine via Claude Code CLI. | AK2: NFR-09 | AL2: =AD2&"|"&COUNTIF(AD$2:AD2,AD2)
A3: LS-002 | B3: Task | C3: LS-EPIC-01 | D3: Extract Figma Make design: screen inventory, tokens, specs | E3: Inventory all screens/states of Figma Make file 2DYtUW39GtnsDpUd5jSu6x; extract tokens, typography, components, motion, copy and accessibility gaps. | F3: – | G3: Delivery clarity – avoids rework | H3: Highest | I3: Must | J3: P0 | K3: Design | L3: SCR-01…SCR-18 | M3: Design pack – all screens (docs/design/screens/) | N3: None | O3: Blocks: LS-003, LS-004, LS-008 Blocked by: – | P3: 1. All prototype screens listed with screenshot 2. Tokens JSON produced 3. Component catalogue and per-screen specs written 4. Missing designs identified | Q3: Std DoD: AC met · no hardcoded strings/colours/dims/config · EN + KN strings present · unit/UI tests pass · lint + translation check pass · screenshots EN/KN attached (UI) · docs updated · human PR review & merge · post-merge verified | R3: Use tokens, string resources (EN+KN) and AppConfig only. | S3: Manual review | T3: docs/design/: 22 screenshots, design-tokens.json, LittleStory_Figma_Design_Details.md | U3: 3 | V3: Medium | W3: Low | X3: UI Integration & Visual Regression Engineer | Y3: Yes | Z3: Low | AA3: – (no code) | AD3: Done | AE3: Project owner (human) | AF3: Not required – design pack supplied | AG3: 18 screens / 22 states inventoried; tokens, typography, components, motion, a11y gaps extracted; 5 missing screens identified | AH3: None | AI3: N/A | AJ3: Completed from supplied design pack: LittleStory_Figma_Design_Details.md, design-tokens.json, 22 screenshots. | AK3: NFR-10 | AL3: =AD3&"|"&COUNTIF(AD$2:AD3,AD3)
A4: LS-003 | B4: Task | C4: LS-EPIC-01 | D4: Requirements catalogue, user journeys A–G and edge cases | E4: Write docs/product/* (vision, FR/NFR from the Requirements sheet, journeys A–G incl. language change, edge cases, MVP scope) and docs/design/screen-inventory.md + screen-state-matrix.md. | F4: – | G4: Delivery clarity – avoids rework | H4: High | I4: Must | J4: P1 | K4: Docs | L4: All | M4: Design pack – all screens (docs/design/screens/) | N4: LS-001, LS-002 | O4: Blocks: LS-006 Blocked by: LS-001, LS-002 | P4: 1. Every FR/NFR has ID, MoSCoW, source, screens, acceptance summary 2. Journeys map to SCR IDs 3. Edge cases include Kannada text expansion, empty states, cancel/retry 4. Unverified items marked as assumptions | Q4: Std DoD: AC met · no hardcoded strings/colours/dims/config · EN + KN strings present · unit/UI tests pass · lint + translation check pass · screenshots EN/KN attached (UI) · docs updated · human PR review & merge · post-merge verified | R4: Use tokens, string resources (EN+KN) and AppConfig only. | S4: Doc review | U4: 5 | V4: High | W4: Low | X4: Product Manager / BA | Y4: Yes | Z4: Low | AA4: claude/project-thread-veobz7 | AD4: In Review | AE4: Project owner (human) | AF4: Approval B granted — awaiting owner review of docs PR | AG4: Drafted 29 Oct 2026: docs/product/* | AH4: None | AI4: N/A | AK4: All FR/NFR | AL4: =AD4&"|"&COUNTIF(AD$2:AD4,AD4)
A5: LS-004 | B5: Task | C5: LS-EPIC-01 | D5: Resolve design gaps & open product decisions | E5: Decision log for: LittleKatha→LittleStory rename in assets; 7 design languages vs EN/KN MVP; missing screens (SCR-19…23); app vs story language; reminders scheduling; demo subscription flag; gendered placeholder copy; greeting time-of-day; transition animations; swipe in onboarding. | F5: – | G5: Delivery clarity – avoids rework | H5: High | I5: Must | J5: P1 | K5: Docs / Design | L5: SCR-19…SCR-23 | M5: Design pack – all screens (docs/design/screens/) | N5: LS-002 | O5: Blocks: LS-046, LS-051, LS-111, LS-113, LS-114, LS-115 Blocked by: LS-002 | P5: 1. Each open question in 'Risks & Questions' has an owner decision or explicit deferral 2. Decisions recorded in docs/project-management/decision-log.md 3. Affected tickets updated | Q5: Std DoD: AC met · no hardcoded strings/colours/dims/config · EN + KN strings present · unit/UI tests pass · lint + translation check pass · screenshots EN/KN attached (UI) · docs updated · human PR review & merge · post-merge verified | R5: Use tokens, string resources (EN+KN) and AppConfig only. | S5: Doc review | U5: 2 | V5: Low | W5: Medium | X5: Technical Product Owner | Y5: Yes | Z5: Low | AA5: claude/project-thread-veobz7 | AD5: In Review | AE5: Project owner (human) | AF5: Approval B granted — awaiting owner review of docs PR | AG5: Drafted 29 Oct 2026: docs/project-management/decision-log.md (D10, D13), docs/design/figma-audit.md | AH5: None | AI5: N/A | AJ5: Blocks LS-046, LS-051, LS-111, LS-113, LS-114, LS-115. | AK5: FR-20, FR-22, FR-23, FR-25 | AL5: =AD5&"|"&COUNTIF(AD$2:AD5,AD5)
A6: LS-005 | B6: Task | C6: LS-EPIC-01 | D6: CLAUDE.md and .github/copilot-instructions.md | E6: Agent instructions mirrored for Claude Code and GitHub Copilot: architecture, no-hardcoding, EN/KN localization, testing, cross-platform, approval levels. | F6: – | G6: Delivery clarity – avoids rework | H6: High | I6: Must | J6: P1 | K6: Repo root | L6: – | M6: – | N6: LS-001 | O6: Blocks: – Blocked by: LS-001 | P6: 1. Both files exist with consistent rules 2. Rules reference docs paths 3. Approval levels A–F stated | Q6: Std DoD: AC met · no hardcoded strings/colours/dims/config · EN + KN strings present · unit/UI tests pass · lint + translation check pass · screenshots EN/KN attached (UI) · docs updated · human PR review & merge · post-merge verified | R6: Shared files: CLAUDE.md, .github/copilot-instructions.md Use tokens, string resources (EN+KN) and AppConfig only. | S6: Doc review | U6: 2 | V6: Low | W6: Low | X6: Orchestrator | Y6: Yes | Z6: Medium | AA6: claude/project-thread-veobz7 | AD6: In Review | AE6: Project owner (human) | AF6: Approval B granted — awaiting owner review of docs PR | AG6: Drafted 29 Oct 2026: CLAUDE.md, .github/copilot-instructions.md | AH6: None | AI6: N/A | AK6: NFR-01, NFR-02, NFR-09 | AL6: =AD6&"|"&COUNTIF(AD$2:AD6,AD6)
A7: LS-006 | B7: Task | C7: LS-EPIC-01 | D7: Prompt library (prompts/00–21) and per-ticket prompts | E7: Create prompts listed in the Prompt Library sheet and prompts/tickets/LS-###.md for each ticket with scope, forbidden changes, l10n and stop conditions. | F7: – | G7: Delivery clarity – avoids rework | H7: Medium | I7: Must | J7: P1 | K7: prompts/ | L7: – | M7: – | N7: LS-003, LS-008 | O7: Blocks: – Blocked by: LS-003, LS-008 | P7: 1. All prompt files exist and do not contradict the master prompt 2. Each ticket prompt includes forbidden-hardcoding rule and EN/KN requirement | Q7: Std DoD: AC met · no hardcoded strings/colours/dims/config · EN + KN strings present · unit/UI tests pass · lint + translation check pass · screenshots EN/KN attached (UI) · docs updated · human PR review & merge · post-merge verified | R7: Use tokens, string resources (EN+KN) and AppConfig only. | S7: Doc review | U7: 3 | V7: Medium | W7: Low | X7: Documentation & Jira Backlog Manager | Y7: Yes | Z7: Low | AA7: claude/project-thread-veobz7 | AD7: In Review | AE7: Project owner (human) | AF7: Approval B granted — awaiting owner review of docs PR | AG7: Drafted 29 Oct 2026: prompts/00–21, prompts/tickets/ (P2) | AH7: None | AI7: N/A | AL7: =AD7&"|"&COUNTIF(AD$2:AD7,AD7)
A8: LS-007 | B8: Task | C8: LS-EPIC-01 | D8: Commit backlog workbook and design reference pack to docs/ | E8: Place this workbook at docs/project-management/ and the design pack at docs/design/ (screens/, design-tokens.json, LittleStory_Figma_Design_Details.md) so hyperlinks resolve. | F8: – | G8: Delivery clarity – avoids rework | H8: Medium | I8: Must | J8: P1 | K8: Docs | L8: All | M8: Design pack – all screens (docs/design/screens/) | N8: LS-001 | O8: Blocks: – Blocked by: LS-001 | P8: 1. Workbook opens with all sheets and images 2. Screenshot hyperlinks resolve from docs/project-management/ 3. Committed on a docs branch via PR | Q8: Std DoD: AC met · no hardcoded strings/colours/dims/config · EN + KN strings present · unit/UI tests pass · lint + translation check pass · screenshots EN/KN attached (UI) · docs updated · human PR review & merge · post-merge verified | R8: Use tokens, string resources (EN+KN) and AppConfig only. | S8: Open workbook; click 3 screenshot links | U8: 1 | V8: Low | W8: Low | X8: Documentation & Jira Backlog Manager | Y8: Yes | Z8: Low | AA8: claude/project-thread-veobz7 | AD8: In Review | AE8: Project owner (human) | AF8: Approval B granted — awaiting owner review of docs PR | AG8: Drafted 29 Oct 2026: docs/ (design pack in PR #1) | AH8: None | AI8: N/A | AL8: =AD8&"|"&COUNTIF(AD$2:AD8,AD8)
A9: LS-008 | B9: Task | C9: LS-EPIC-01 | D9: Architecture ADRs (ADR-001…015) | E9: Write ADRs listed in the Architecture Decisions sheet with options, rationale, consequences; status Proposed until owner approval. | F9: – | G9: Delivery clarity – avoids rework | H9: High | I9: Must | J9: P1 | K9: Docs / Architecture | L9: – | M9: – | N9: LS-001, LS-002 | O9: Blocks: LS-006, LS-030, LS-031 Blocked by: LS-001, LS-002 | P9: 1. 15 ADRs in docs/architecture/adr/ 2. Each references affected tickets 3. Owner approves or comments | Q9: Std DoD: AC met · no hardcoded strings/colours/dims/config · EN + KN strings present · unit/UI tests pass · lint + translation check pass · screenshots EN/KN attached (UI) · docs updated · human PR review & merge · post-merge verified | R9: Use tokens, string resources (EN+KN) and AppConfig only. | S9: Doc review | U9: 3 | V9: Medium | W9: Low | X9: Android Principal Architect | Y9: Yes | Z9: Low | AA9: claude/project-thread-veobz7 | AD9: In Review | AE9: Project owner (human) | AF9: Approval B granted — awaiting owner review of docs PR | AG9: Drafted 29 Oct 2026: docs/architecture/adr/ADR-001…018 | AH9: None | AI9: N/A | AK9: NFR-05 | AL9: =AD9&"|"&COUNTIF(AD$2:AD9,AD9)
A10: LS-010 | B10: Story | C10: LS-EPIC-02 | D10: Colour tokens → Compose theme | E10: Implement all colours from design-tokens.json as named tokens: Material3 ColorScheme mapping + LittleStoryColors extension (night, night-surface, success-bg, favourite, story-art gradients, illustration colours). Single light theme with night surfaces (ADR-013). | F10: As a developer, I want every colour as a named token so design changes happen in one place. | G10: Visual fidelity and consistency | H10: High | I10: Must | J10: P2 | K10: :core:designsystem | L10: All | M10: Design pack – all screens (docs/design/screens/) | N10: LS-031 | O10: Blocks: LS-014, LS-015, LS-018, LS-150 Blocked by: LS-031 | P10: 1. Every token in design-tokens.json exists exactly once in :core:designsystem 2. No hex literal outside token files (lint/detekt check) 3. Preview sheet shows all swatches | Q10: Std DoD: AC met · no hardcoded strings/colours/dims/config · EN + KN strings present · unit/UI tests pass · lint + translation check pass · screenshots EN/KN attached (UI) · docs updated · human PR review & merge · post-merge verified | R10: Shared files: core/designsystem/theme/Color.kt Use tokens, string resources (EN+KN) and AppConfig only. | S10: Unit: token map completeness test vs JSON · Screenshot: colour swatch preview | U10: 3 | V10: Medium | W10: Low | X10: Jetpack Compose UI Engineer | Y10: After deps | Z10: High | AA10: feature/LS-010-colour-tokens-compose-theme | AD10: To Do | AE10: Project owner (human) | AF10: Awaiting Approval C | AH10: None | AI10: N/A | AK10: NFR-01, NFR-10 | AL10: =AD10&"|"&COUNTIF(AD$2:AD10,AD10)
A11: LS-011 | B11: Story | C11: LS-EPIC-02 | D11: Typography: DM Sans + Manrope + Kannada fallback, type scale | E11: Bundle DM Sans (400–700) and Manrope (500–800) as res/font (OFL – record licence), add Noto Sans Kannada (OFL) fallback, define type scale from design (onboarding 29/1.12, hero 25/1.12, topbar 17/800, reader 16/1.95, chip 12/600, eyebrow 10/800 +1.6, nav 10/600). Kannada line-height adjustments. | F11: As a Kannada-speaking parent, I want text to render clearly in my script. | G11: Visual fidelity and consistency | H11: High | I11: Must | J11: P2 | K11: :core:designsystem | L11: All | M11: Design pack – all screens (docs/design/screens/) | N11: LS-031 | O11: Blocks: LS-014, LS-015 Blocked by: LS-031 | P11: 1. All text styles from design spec available as theme tokens 2. Kannada renders with correct glyphs in every style 3. Licences listed in Help & about / docs 4. No inline TextStyle in feature code | Q11: Std DoD: AC met · no hardcoded strings/colours/dims/config · EN + KN strings present · unit/UI tests pass · lint + translation check pass · screenshots EN/KN attached (UI) · docs updated · human PR review & merge · post-merge verified | R11: Shared files: core/designsystem/theme/Type.kt, res/font Use tokens, string resources (EN+KN) and AppConfig only. | S11: Screenshot: type specimen EN + KN at font scale 1.0 and 1.5 | U11: 5 | V11: High | W11: Medium | X11: Jetpack Compose UI Engineer | Y11: After deps | Z11: High | AA11: feature/LS-011-typography-dm-sans-manrope-kannada | AD11: To Do | AE11: Project owner (human) | AF11: Awaiting Approval C | AH11: Layout risk | AI11: Missing | AK11: NFR-01, NFR-02 | AL11: =AD11&"|"&COUNTIF(AD$2:AD11,AD11)
A12: LS-012 | B12: Story | C12: LS-EPIC-02 | D12: Shape, spacing, elevation and motion tokens | E12: Radii (lg 24, md 18, sm 13, button 16, hero 26, sheet 32 top, chip 20, avatar 15/19), spacing scale, shadows (shadow, soft, primary-button, hero, create-nav), layout constants (topbar 68, bottom nav 76, content padding 20/16 compact), motion durations (twinkle 2.4/1.7/1.1 s, button .18 s, toggle .2 s, progress .2/.3 s). | F12: – | G12: Visual fidelity and consistency | H12: High | I12: Must | J12: P2 | K12: :core:designsystem | L12: All | M12: Design pack – all screens (docs/design/screens/) | N12: LS-031 | O12: Blocks: LS-015, LS-018 Blocked by: LS-031 | P12: 1. Tokens defined once in designsystem 2. Compact (≤360dp) and tall (≥900dp) variants handled via window size, not hardcoded checks 3. Reduced-motion flag disables infinite twinkle | Q12: Std DoD: AC met · no hardcoded strings/colours/dims/config · EN + KN strings present · unit/UI tests pass · lint + translation check pass · screenshots EN/KN attached (UI) · docs updated · human PR review & merge · post-merge verified | R12: Shared files: core/designsystem/theme/Dimens.kt, Shape.kt, Motion.kt Use tokens, string resources (EN+KN) and AppConfig only. | S12: Unit: token values · Screenshot: spacing/shape preview | U12: 3 | V12: Medium | W12: Low | X12: Jetpack Compose UI Engineer | Y12: After deps | Z12: High | AA12: feature/LS-012-shape-spacing-elevation-and-motion | AD12: To Do | AE12: Project owner (human) | AF12: Awaiting Approval C | AH12: None | AI12: N/A | AK12: NFR-01, NFR-04 | AL12: =AD12&"|"&COUNTIF(AD$2:AD12,AD12)
A13: LS-013 | B13: Story | C13: LS-EPIC-02 | D13: Icon set (21 line icons) as vector drawables | E13: Recreate icons home, compass, plus, book, user, bell, search, heart, download, play, pause, back, chevron, clock, check, close, edit, moon, settings, volume (24×24, 1.8 stroke, round caps) + filled variants for active heart/download. Add proper rewind-15/forward-15 icons (replaces overlapping glyphs). | F13: – | G13: Visual fidelity and consistency | H13: Medium | I13: Must | J13: P2 | K13: :core:designsystem | L13: All | M13: Design pack – all screens (docs/design/screens/) | N13: LS-031 | O13: Blocks: LS-019, LS-094 Blocked by: LS-031 | P13: 1. All icons in res/drawable with consistent naming ic_* 2. Auto-mirroring set where directional (back, chevron) for RTL 3. Icon catalogue preview | Q13: Std DoD: AC met · no hardcoded strings/colours/dims/config · EN + KN strings present · unit/UI tests pass · lint + translation check pass · screenshots EN/KN attached (UI) · docs updated · human PR review & merge · post-merge verified | R13: Use tokens, string resources (EN+KN) and AppConfig only. | S13: Screenshot: icon catalogue | U13: 3 | V13: Medium | W13: Low | X13: Jetpack Compose UI Engineer | Y13: Yes | Z13: Low | AA13: feature/LS-013-icon-set-21-line-icons | AD13: To Do | AE13: Project owner (human) | AF13: Awaiting Approval C | AH13: None | AI13: N/A | AK13: NFR-10 | AL13: =AD13&"|"&COUNTIF(AD$2:AD13,AD13)
